Workbook

Sheet Дашборд
B2: Дашборд фонда PH-2026 | AA2: Археология | AB2: Доисторическая эра | AC2: Синий | AD2: ОТМЕНЁН
B3: Живые показатели по листу «Реестр» · v4.9 · 20.10.2026 | AA3: Ушли и прочие | AB3: Артефакт | AC3: Silver
B4: Ключевые показатели | AA4: Ветераны | AB4: Ушёл | AC4: —
B5: Всего записей | D5: =COUNTA(Реестр!A2:A36) | AA5: На службе | AB5: Убит яростью | AC5: Yellow
B6: Экспонатов (не отказные заказы) | D6: =COUNTA(Реестр!A2:A36)-D7 | AA6: Альтернативная ветка | AB6: Бесследно утерян | AC6: Black
B7: Отказных заказов (статус «отказ владельца») | D7: =SUMPRODUCT(--ISNUMBER(SEARCH("отказ",Реестр!Q2:Q36))) | AA7: Подтехники | AB7: Источник «грязного провода» | AC7: Pearl White
B8: Сумма фонда (без отказных) | D8: =SUMIFS(Реестр!N2:N36,Реестр!Q2:Q36,"<>*отказ*") | AB8: Умер от грязного провода | AC8: Gold
B9: Средняя цена (без отказных) | D9: =IFERROR(AVERAGEIFS(Реестр!N2:N36,Реестр!Q2:Q36,"<>*отказ*"),0) | AB9: Ветеран | AC9: Polar Black
B10: Самая дорогая покупка | D10: =MAX(Реестр!N2:N36) | AB10: Ушёл по невыгодному обмену | AC10: Luna Blue
B11: Год первого прихода | D11: =MIN(Реестр!E2:E36) | AB11: Изгнан | AC11: Forest Green
B12: Год последнего прихода | D12: =MAX(Реестр!E2:E36) | AB12: Ветеран 2023 — 10.10.2026, ушёл на заслуженный отдых | AC12: White
AB13: Продан ради съёмного дома | AC13: Silver Shadow
AB14: Бартер за наушники | AC14: Cosmic Orange
B15: Разбор по категориям | AB15: Кнопочный резерв | AC15: Storm Black
B16: Археология | D16: =COUNTIF(Реестр!C2:C36,B16) | AB16: Найден убитым | AC16: Black+Gunmetal
B17: Ушли и прочие | D17: =COUNTIF(Реестр!C2:C36,B17) | AB17: Король — Основной | AC17: Grey
B18: Ветераны | D18: =COUNTIF(Реестр!C2:C36,B18) | AB18: Отменён — отказ владельца | AC18: Blue
B19: На службе | D19: =COUNTIF(Реестр!C2:C36,B19) | AB19: Альтернативная ветка | AC19: Dark Flare
B20: Альтернативная ветка | D20: =COUNTIF(Реестр!C2:C36,B20) | AB20: Отказ владельца — отменён в пользу Pad 7
B21: Подтехники | D21: =COUNTIF(Реестр!C2:C36,B21) | AB21: Отказ владельца — отменён до получения
B22: Проверка суммы | D22: =SUM(D16:D21) | AB22: Отказ владельца
AB23: ЗАКРЫТО
B24: Приходы по годам (₽, без отказных) | AB24: Запасной оператор связи на тяжёлые времена
B25: Год | D25: Сумма | E25: Приборов | F25: Кто пришёл | AB25: ВЫЧЕРКНУТ
B26: 2007 | D26: =SUMIFS(Реестр!$N$2:$N$36,Реестр!$E$2:$E$36,B26,Реестр!$Q$2:$Q$36,"<>*отказ*") | E26: =COUNTIFS(Реестр!$E$2:$E$36,B26,Реестр!$Q$2:$Q$36,"<>*Отказ владельца*") | F26: Samsung SGH-C130 | AB26: Основной запасной — преемник Infinix Hot 30 Play
B27: 2008 | D27: =SUMIFS(Реестр!$N$2:$N$36,Реестр!$E$2:$E$36,B27,Реестр!$Q$2:$Q$36,"<>*отказ*") | E27: =COUNTIFS(Реестр!$E$2:$E$36,B27,Реестр!$Q$2:$Q$36,"<>*Отказ владельца*") | F27: — | AB27: Подтехника — на службе
B28: 2009 | D28: =SUMIFS(Реестр!$N$2:$N$36,Реестр!$E$2:$E$36,B28,Реестр!$Q$2:$Q$36,"<>*отказ*") | E28: =COUNTIFS(Реестр!$E$2:$E$36,B28,Реестр!$Q$2:$Q$36,"<>*Отказ владельца*") | F28: — | AB28: На службе
B29: 2010 | D29: =SUMIFS(Реестр!$N$2:$N$36,Реестр!$E$2:$E$36,B29,Реестр!$Q$2:$Q$36,"<>*отказ*") | E29: =COUNTIFS(Реестр!$E$2:$E$36,B29,Реестр!$Q$2:$Q$36,"<>*Отказ владельца*") | F29: Samsung E250, Nokia 6300, Безымянные кнопочные
B30: 2011 | D30: =SUMIFS(Реестр!$N$2:$N$36,Реестр!$E$2:$E$36,B30,Реестр!$Q$2:$Q$36,"<>*отказ*") | E30: =COUNTIFS(Реестр!$E$2:$E$36,B30,Реестр!$Q$2:$Q$36,"<>*Отказ владельца*") | F30: —
B31: 2012 | D31: =SUMIFS(Реестр!$N$2:$N$36,Реестр!$E$2:$E$36,B31,Реестр!$Q$2:$Q$36,"<>*отказ*") | E31: =COUNTIFS(Реестр!$E$2:$E$36,B31,Реестр!$Q$2:$Q$36,"<>*Отказ владельца*") | F31: Samsung Galaxy Mini 2
B32: 2013 | D32: =SUMIFS(Реестр!$N$2:$N$36,Реестр!$E$2:$E$36,B32,Реестр!$Q$2:$Q$36,"<>*отказ*") | E32: =COUNTIFS(Реестр!$E$2:$E$36,B32,Реестр!$Q$2:$Q$36,"<>*Отказ владельца*") | F32: —
B33: 2014 | D33: =SUMIFS(Реестр!$N$2:$N$36,Реестр!$E$2:$E$36,B33,Реестр!$Q$2:$Q$36,"<>*отказ*") | E33: =COUNTIFS(Реестр!$E$2:$E$36,B33,Реестр!$Q$2:$Q$36,"<>*Отказ владельца*") | F33: Lenovo A328
B34: 2015 | D34: =SUMIFS(Реестр!$N$2:$N$36,Реестр!$E$2:$E$36,B34,Реестр!$Q$2:$Q$36,"<>*отказ*") | E34: =COUNTIFS(Реестр!$E$2:$E$36,B34,Реестр!$Q$2:$Q$36,"<>*Отказ владельца*") | F34: Lenovo Tab 2 A10-70L
B35: 2016 | D35: =SUMIFS(Реестр!$N$2:$N$36,Реестр!$E$2:$E$36,B35,Реестр!$Q$2:$Q$36,"<>*отказ*") | E35: =COUNTIFS(Реестр!$E$2:$E$36,B35,Реестр!$Q$2:$Q$36,"<>*Отказ владельца*") | F35: BQ Strike
B36: 2017 | D36: =SUMIFS(Реестр!$N$2:$N$36,Реестр!$E$2:$E$36,B36,Реестр!$Q$2:$Q$36,"<>*отказ*") | E36: =COUNTIFS(Реестр!$E$2:$E$36,B36,Реестр!$Q$2:$Q$36,"<>*Отказ владельца*") | F36: BQ-5035 Velvet
B37: 2018 | D37: =SUMIFS(Реестр!$N$2:$N$36,Реестр!$E$2:$E$36,B37,Реестр!$Q$2:$Q$36,"<>*отказ*") | E37: =COUNTIFS(Реестр!$E$2:$E$36,B37,Реестр!$Q$2:$Q$36,"<>*Отказ владельца*") | F37: Sony Xperia Z1 (C6903)
B38: 2019 | D38: =SUMIFS(Реестр!$N$2:$N$36,Реестр!$E$2:$E$36,B38,Реестр!$Q$2:$Q$36,"<>*отказ*") | E38: =COUNTIFS(Реестр!$E$2:$E$36,B38,Реестр!$Q$2:$Q$36,"<>*Отказ владельца*") | F38: —
B39: 2020 | D39: =SUMIFS(Реестр!$N$2:$N$36,Реестр!$E$2:$E$36,B39,Реестр!$Q$2:$Q$36,"<>*отказ*") | E39: =COUNTIFS(Реестр!$E$2:$E$36,B39,Реестр!$Q$2:$Q$36,"<>*Отказ владельца*") | F39: —
B40: 2021 | D40: =SUMIFS(Реестр!$N$2:$N$36,Реестр!$E$2:$E$36,B40,Реестр!$Q$2:$Q$36,"<>*отказ*") | E40: =COUNTIFS(Реестр!$E$2:$E$36,B40,Реестр!$Q$2:$Q$36,"<>*Отказ владельца*") | F40: Infinix Hot 11
... B45: 2026 | D45: =SUMIFS(Реестр!$N$2:$N$36,Реестр!$E$2:$E$36,B45,Реестр!$Q$2:$Q$36,"<>*отказ*") | E45: =COUNTIFS(Реестр!$E$2:$E$36,B45,Реестр!$Q$2:$Q$36,"<>*Отказ владельца*") | F45: Samsung S25+, iPhone 17 Pro Max, Soyes F8 Pro Max, Nokia 6300 (Silver), Realme C75, POCO F9 Ultra, OnePlus 15 (CPH2749), Xiaomi Pad 7, Philips Xenium X175, Redmi Note 13 5G, Infinix GT 30 Pro, Xiaomi HyperCharge Power Bank 25000 (212 Вт)
...

Sheet Обложка
B2: ЦИФРОВОЕ ХРОНОЛОГИЧЕСКОЕ ИЗДАНИЕ 2026
B3: EXCEL-ВЕРСИЯ ФОНДА
B5: Инвентарный № | C5: PH-2026
B6: Записей | C6: 35
B7: Охват | C7: 2007–2026 · 20 лет
B8: Экспонатов | C8: 28 · отказных заказов: 7
B9: Место | C9: Россия, Республика Крым,
C10: с. Ильинка, Красноперекопский район
B11: Основание фонда | C11: 26 сентября 2026 г.
B12: Автор | C12: Лысогорский Д. С.
B13: Соавтор | C13: Яндекс Алиса (поиск информации)
B14: Excel-сборка | C14: 17.10.2026 — v4.8 · отмена подтехник № 14.1 (HOCO X50) и № 14.2 (Xiaomi 120W HyperCharge): дубль комплектного кабеля и блока питания Короля; № 17 (Xiaomi Pad 7) → ЗАКРЫТО; память 0a/0b/0c → МБ; чистка огрызков эмодзи (v4.7: приход № 21 TeXet TM-130) · v4.9 (20.10.2026): дашборд с живыми формулами, выпадающие списки, цветовая шкала цен, красный штамп ОТМЕНЁН, диаграммы приходов и батарей
B15: Модернизация v4.9.3 · 20.10.2026 — печать № 21: префикс Статистики (62 формулы), Итого-суммы, MIN/MAX-хелпер вместо MINIFS/MAXIFS, ширины колонок, лог-шкала графика приходов, доп. колонки таблиц Дашборда, фикс гиперссылок дел | C15: v4.9.1 · печать № 19 · 20.10.2026 · фикс формул Статистики и KPI отказных (канон: 7)
B16: Легенда категорий
B17: На службе | C17: 5
B18: Ветераны | C18: 2
B19: Подтехники | C19: 1
B20: В пути · упразднена 16.10.2026 | C20: 0
B21: Альтернативная ветка | C21: 1
B22: Археология | C22: 5
B23: Ушли и прочие | C23: 21
B25: История правок ведётся на листе «Исправления»

Sheet Реестр
A1: ID | B1: Устройство | C1: Категория | D1: Год модели | E1: Год прихода | F1: ПЗУ (ГБ) | G1: ОЗУ (ГБ) | H1: Экран (") | I1: Гц | J1: Батарея (мАч) | K1: Камера (МП) | L1: CPU (ГГц) | M1: Зарядка (Вт) | N1: Цена (₽) | O1: Цена (текст) | P1: Память (текст) | Q1: Статус | R1: Цвет | S1: Источник | T1: Заметки | U1: → Дело | V1: Флаг | W1: Цена купл. (хелпер)
A2: 0a | B2: Samsung SGH-C130 | C2: Археология | D2: 2007 | E2: 2007 | F2: 2 МБ | H2: 1.5 | J2: 800 | N2: 2300 | O2: ~2 300 ₽ | P2: 2 МБ | Q2: Доисторическая эра | R2: Синий | S2: — | T2: 1,5" CSTN (128×128), 65 536 цветов. Батарея 800 мАч. Вес 75 г. Лёгкий, FM-радио. | U2: =HYPERLINK("#'Личные дела'!A2","открыть ▸") | W2: =IF(AND($N2>0,NOT(ISNUMBER(SEARCH("Отказ владельца",$Q2)))),$N2,"")
A3: 0b | B3: Samsung E250 | C3: Археология | D3: 2010 | E3: 2010 | F3: 10 МБ | G3: 16 МБ | H3: 2 | J3: 800 | K3: 0.3 | L3: 0.23 | N3: 2630 | O3: ~2 630 ₽ | P3: 10 МБ + microSD до 2 ГБ | Q3: Доисторическая эра | R3: Silver | S3: — | T3: 2" TFT (128×160), 0,3 МП камера. ARM9 230 МГц. ОЗУ 16 МБ. Батарея 800 мАч. Звук выдвижения — «душа телефона». | U3: =HYPERLINK("#'Личные дела'!A3","открыть ▸") | W3: =IF(AND($N3>0,NOT(ISNUMBER(SEARCH("Отказ владельца",$Q3)))),$N3,"") | X3: =IF(ISNUMBER(SEARCH("Отказ владельца",$Q3)),"ОТКАЗ","ОК")
A4: 0c | B4: Nokia 6300 | C4: Археология | D4: 2010 | E4: 2010 | F4: 7,8 МБ | H4: 2 | J4: 860 | K4: 2 | N4: 5415 | O4: ~4 170–5 415 ₽ | P4: 7,8 МБ + microSD до 2 ГБ | Q4: Доисторическая эра | R4: Silver | S4: — | T4: 2" TFT (240×320), 2 МП камера. Батарея 860 мАч. Корпус: сталь + пластик. Икона эпохи, вторая как резерв. | U4: =HYPERLINK("#'Личные дела'!A4","открыть ▸") | W4: =IF(AND($N4>0,NOT(ISNUMBER(SEARCH("Отказ владельца",$Q4)))),$N4,"") | Y4: =IF(ISNUMBER(SEARCH("Отказ владельца",$Q4)),"ОТКАЗ","ОК")
A5: 0d | B5: Безымянные кнопочные | C5: Археология | D5: 2010 | E5: 2010 | O5: — | P5: — | Q5: Доисторическая эра | R5: — | S5: — | T5: «Серые» аппараты, без точных характеристик. | U5: =HYPERLINK("#'Личные дела'!A5","открыть ▸") | W5: =IF(AND($N5>0,NOT(ISNUMBER(SEARCH("Отказ владельца",$Q5)))),$N5,"") | Z5: =IF(ISNUMBER(SEARCH("Отказ владельца",$Q5)),"ОТКАЗ","ОК")
A6: 1 | B6: Samsung Galaxy Mini 2 | C6: Археология | D6: 2012 | E6: 2012 | F6: 4 | G6: 0.512 | H6: 3.27 | J6: 1300 | K6: 3 | L6: 0.8 | N6: 8990 | O6: ~8 490–8 990 ₽ | P6: 4 ГБ + microSD до 32 ГБ | Q6: Артефакт | R6: Yellow | S6: — | T6: 3,27" TFT (320×480), 3 МП камера. Qualcomm MSM7227A 800 МГц. ОЗУ 512 МБ. Android 2.3. Батарея 1 300 мАч. Первый смартфон, открыл интернет. | U6: =HYPERLINK("#'Личные дела'!A6","открыть ▸") | W6: =IF(AND($N6>0,NOT(ISNUMBER(SEARCH("Отказ владельца",$Q6)))),$N6,"") | AA6: =IF(ISNUMBER(SEARCH("Отказ владельца",$Q6)),"ОТКАЗ","ОК")
A7: 2 | B7: Lenovo A328 | C7: Ушли и прочие | D7: 2014 | E7: 2014 | F7: 4 | G7: 1 | H7: 4.5 | J7: 2000 | K7: 5 | L7: 1.3 | N7: 4490 | O7: ~4 490 ₽ | P7: 1 ГБ ОЗУ, 4 ГБ ПЗУ + microSD до 32 ГБ | Q7: Ушёл | R7: Black | S7: — | T7: 4,5" TFT (854×480). MediaTek MT6582M, 4×1,3 ГГц. Android 4.4. Камеры 5 МП + 2 МП. Батарея 2 000 мАч (съёмная). 132×68,5×11 мм, 140 г. 2 SIM. Опознан по фото владельца. В школе по приколу хотели выкинуть из окна с третьего этажа. | U7: =HYPERLINK("#'Личные дела'!A7","открыть ▸") | W7: =IF(AND($N7>0,NOT(ISNUMBER(SEARCH("Отказ владельца",$Q7)))),$N7,"") | AB7: =IF(ISNUMBER(SEARCH("Отказ владельца",$Q7)),"ОТКАЗ","ОК")
A8: 2b | B8: Lenovo Tab 2 A10-70L | C8: Ушли и прочие | D8: 2015 | E8: 2015 | F8: 16 | G8: 2 | H8: 10.1 | J8: 7000 | N8: 17990 | O8: ~17 990 ₽ | P8: 2 ГБ ОЗУ, 16 ГБ ПЗУ + microSD до 64 ГБ | Q8: Убит яростью | R8: Pearl White | S8: — | T8: 10,1" IPS (1920×1200). MediaTek MT8732. Android 4.4 → 5.0. Батарея 7000 мАч. 247×171×8,9 мм, 509 г. Любил слушать музыку . Geometry Dash ставил паузу каждые несколько секунд — разбит кулаком/коленом. Модель опознана по фото владельца. | U8: =HYPERLINK("#'Личные дела'!A8","открыть ▸") | W8: =IF(AND($N8>0,NOT(ISNUMBER(SEARCH("Отказ владельца",$Q8)))),$N8,"") | AC8: =IF(ISNUMBER(SEARCH("Отказ владельца",$Q8)),"ОТКАЗ","ОК")
A9: 2c | B9: Sony Xperia Z1 (C6903) | C9: Ушли и прочие | D9: 2013 | E9: 2018 | F9: 16 | G9: 2 | H9: 5 | J9: 3000 | K9: 20.7 | L9: 2.2 | O9: Дар (вероятно, от отца); старт 2013: ~29 990 ₽ | P9: 16 ГБ + microSD до 64 ГБ, ОЗУ 2 ГБ | Q9: Ушёл | R9: Black | S9: — | T9: 5" TFT (1920×1080), 16:9. Snapdragon 800 (MSM8974), 4×2,2 ГГц. Камера 20,7 МП Exmor RS, фронт 2 МП. Батарея 3 000 мАч (несъёмная). Android 4.2.2 → 5.1.1. IP55/IP58: заглушки на USB и слоте карт, кнопка спуска камеры на правом боку. OmniBalance: 146×74×8,5 мм, 171 г. Опознан по фото владельца; 16.10.2026 переприписан с Xperia 1 (J9110) по памяти владельца. | U9: =HYPERLINK("#'Личные дела'!A9","открыть ▸") | W9: =IF(AND($N9>0,NOT(ISNUMBER(SEARCH("Отказ владельца",$Q9)))),$N9,"") | AD9: =IF(ISNUMBER(SEARCH("Отказ владельца",$Q9)),"ОТКАЗ","ОК")
A10: 3 | B10: BQ-5035 Velvet | C10: Ушли и прочие | D10: 2017 | E10: 2017 | F10: 8 | G10: 1 | H10: 5 | J10: 2000 | K10: 8 | L10: 1.3 | N10: 4190 | O10: 2 500 ₽ (покупка); ~4 190 ₽ (старт продаж) | P10: 8 ГБ + microSD до 64 ГБ, ОЗУ 1 ГБ | Q10: Бесследно утерян | R10: Gold | S10: «Парк» | T10: 5" IPS (854×480), 8 МП + 5 МП камеры. MediaTek MT6580M 1,3 ГГц. Android 7.0. Батарея 2 000 мАч — сдулась к прим. 2022. Разряжался на 30–40% за 30–40 минут поездки. Год выпуска подтверждён: сентябрь 2017. | U10: =HYPERLINK("#'Личные дела'!A10","открыть ▸") | W10: =IF(AND($N10>0,NOT(ISNUMBER(SEARCH("Отказ владельца",$Q10)))),$N10,"") | AE10: =IF(ISNUMBER(SEARCH("Отказ владельца",$Q10)),"ОТКАЗ","ОК")
A11: 4 | B11: BQ Strike | C11: Ушли и прочие | D11: 2016 | E11: 2016 | F11: 8 | G11: 1 | H11: 5 | J11: 2000 | K11: 13 | L11: 1.3 | N11: 2500 | O11: ~2 500 ₽ | P11: 8 ГБ + microSD до 32 ГБ, ОЗУ 1 ГБ | Q11: Источник «грязного провода» | R11: Синий | S11: Сарай | T11: 5" IPS (1280×720), 13 МП + 5 МП камеры. MediaTek MT6580 1,3 ГГц. Android 6.0. Металлический корпус. Батарея 2 000 мАч. Провод убил Infinix. | U11: =HYPERLINK("#'Личные дела'!A11","открыть ▸") | W11: =IF(AND($N11>0,NOT(ISNUMBER(SEARCH("Отказ владельца",$Q11)))),$N11,"") | AF11: =IF(ISNUMBER(SEARCH("Отказ владельца",$Q11)),"ОТКАЗ","ОК")
A12: 5 | B12: Infinix Hot 11 | C12: Ушли и прочие | D12: 2021 | E12: 2021 | F12: 128 | G12: 4 | H12: 6.82 | I12: 90 | J12: 6000 | K12: 50 | N12: 11000 | O12: 11 000 ₽ | P12: 128 ГБ + microSD до 512 ГБ, ОЗУ 4 ГБ | Q12: Умер от грязного провода | R12: Polar Black | S12: WB | T12: 6,82" IPS (720×1640), 90 Гц. 50 МП + 2 МП, фронт. 8 МП. Helio G37. Android 11. Батарея 6 000 мАч. Micro-USB. + смарт-часы (палёные) и наушники. | U12: =HYPERLINK("#'Личные дела'!A12","открыть ▸") | W12: =IF(AND($N12>0,NOT(ISNUMBER(SEARCH("Отказ владельца",$Q12)))),$N12,"") | AG12: =IF(ISNUMBER(SEARCH("Отказ владельца",$Q12)),"ОТКАЗ","ОК")
A13: 6 | B13: Infinix Hot 20i (X665E) | C13: Ветераны | D13: 2022 | E13: 2025 | H13: 6.6 | I13: 60 | J13: 5000 | K13: 13 | L13: 2 | M13: 10 | N13: 7000 | O13: 7 000 ₽ | P13: Уточняется (варианты 4/64 · 4/128 · 6/128) + microSD до 512 ГБ | Q13: Ветеран | R13: Luna Blue | S13: У товарища | T13: 6,6" IPS (1612×720), 60 Гц, 500 нит. Helio G25 (8×A53, до 2,0 ГГц, 12 нм). 13 МП (f/1.85) + 2 МП + 0,8 МП AI, фронт. 8 МП со вспышкой. Android 12 (XOS 10.6). Батарея 5 000 мАч, 10 Вт. Micro-USB (OTG), без NFC. Числился как Hot 12 Pro — опознан 15.10.2026 через GT 30 Pro (№ 20). Выживший. | U13: =HYPERLINK("#'Личные дела'!A13","открыть ▸") | W13: =IF(AND($N13>0,NOT(ISNUMBER(SEARCH("Отказ владельца",$Q13)))),$N13,"") | AH13: =IF(ISNUMBER(SEARCH("Отказ владельца",$Q13)),"ОТКАЗ","ОК")
A14: 6b | B14: Honor X7c | C14: Ушли и прочие | D14: 2024 | E14: 2024 | F14: 512 | G14: 8 | H14: 6.77 | I14: 120 | J14: 5200 | K14: 108 | L14: 2.8 | M14: 35 | O14: покупка (цена не зафиксирована) | P14: 512 ГБ + microSD, ОЗУ 8 ГБ | Q14: Ушёл по невыгодному обмену | R14: Forest Green | S14: Магазин; далее — обмен сослуживцу | T14: 6,77" IPS HD+ (1610×720, 261 ppi, 850 нит), заявленные 120 Гц. 108 МП + 2 МП, фронт. 8 МП. Snapdragon 685 (SM6225, 4×A73 2,8 ГГц + 4×A53 1,9 ГГц, 6 нм), Adreno 610, ~300 000+ AnTuTu v10. Android 14, MagicOS 8. Батарея 5200 мАч, 35 Вт SuperCharge (~1 ч 15 мин до 100%). IP64 + сертифицированная ударопрочность, NFC, стерео, ИК-порт, 3,5 мм, microSD, USB-C 2.0 с OTG. 4G (без 5G), Wi-Fi 5, BT 5.0. Зелёная версия: 8,24 мм, 196 г, «кожаная» спинка. Куплен осознанно, обменян по глупости сослуживцу на аппарат заведомо более слабый: проверить состояние сразу не удалось, обратный обмен был отклонён. Первый Honor в фонде (не считая № 7, карточка которого продавалась под видом Honor 200). Первый честный 512 ГБ в основной линии. Единственная сделка фонда без кнопки «отменить». | U14: =HYPERLINK("#'Личные дела'!A14","открыть ▸") | W14: =IF(AND($N14>0,NOT(ISNUMBER(SEARCH("Отказ владельца",$Q14)))),$N14,"") | AI14: =IF(ISNUMBER(SEARCH("Отказ владельца",$Q14)),"ОТКАЗ","ОК")
A15: 7 | B15: P901 (OPPO CPH1821EX) | C15: Ушли и прочие | D15: 2023 | E15: 2023 | F15: 512 | G15: 4 | H15: 6.2 | J15: 6000 | L15: 2 | N15: 6818 | O15: 6 818 ₽ | P15: 512 ГБ (498 ГБ свободно, настоящие), ОЗУ 4 ГБ LPDDR4X (в прошивке — 12 ГБ, завышено) | Q15: Изгнан | R15: White | S15: Ozon | T15: Контрафакт на базе OPPO F7 (CPH1821EX). Реальное железо: MediaTek Helio P60 (MT6771, 4×A73 + 4×A53, 2,0 ГГц, 12 нм), GPU Mali-G72 MP3, 4 ГБ LPDDR4X, 6,2" IPS 2280×1080. Прошивка-обманка: Android 10 + ColorOS V7.1 поверх Android 8.1, ОЗУ завышено до 12 ГБ. Накопитель 512 ГБ — настоящий. Батарея 6 000 мАч (оригинал Oppo F7 — 3 400 мАч, заменена). SIM-карта отсутствует. Нет GMS-сертификации — банки и Госуслуги не работают. Приложения вылетают. Осознанное изгнание, но жив. Настоящее имя раскрыто через ВК: OPPO CPH1821EX. | U15: =HYPERLINK("#'Личные дела'!A15","открыть ▸") | W15: =IF(AND($N15>0,NOT(ISNUMBER(SEARCH("Отказ владельца",$Q15)))),$N15,"") | AJ15: =IF(ISNUMBER(SEARCH("Отказ владельца",$Q15)),"ОТКАЗ","ОК")
A16: 8 | B16: Infinix Hot 30 Play | C16: Ветераны | D16: 2023 | E16: 2023 | F16: 128 | G16: 8 | H16: 6.82 | I16: 90 | J16: 6000 | K16: 16 | M16: 18 | N16: 12000 | O16: 11–12 тыс ₽ | P16: 128 ГБ + microSD до 1 ТБ, ОЗУ 8 ГБ | Q16: Ветеран 2023 — 10.10.2026, ушёл на заслуженный отдых | R16: Black | S16: WB | T16: 6,82" IPS (1640×720), 90 Гц. 16 МП + QVGA, фронт. 8 МП. Helio G37. Android 13. Батарея 6 000 мАч, 18 Вт. USB-C, NFC. «Будущий жёлтый самсунг»: к 2031 ≈ Mini 2. | U16: =HYPERLINK("#'Личные дела'!A16","открыть ▸") | W16: =IF(AND($N16>0,NOT(ISNUMBER(SEARCH("Отказ владельца",$Q16)))),$N16,"") | AK16: =IF(ISNUMBER(SEARCH("Отказ владельца",$Q16)),"ОТКАЗ","ОК")
A17: 9 | B17: Samsung S25+ | C17: Ушли и прочие | D17: 2026 | E17: 2026 | F17: 512 | G17: 12 | H17: 6.7 | I17: 120 | J17: 4900 | K17: 50 | M17: 25 | N17: 90000 | O17: 90 000 ₽ | P17: 512 ГБ, ОЗУ 12 ГБ | Q17: Продан ради съёмного дома | R17: Silver Shadow | S17: DNS | T17: 6,7" Dynamic AMOLED 2X (QHD+, 1–120 Гц), 2600 нит. 50 МП (OIS) + 12 МП + 10 МП (3×), фронт. 12 МП. Snapdragon 8 Elite for Galaxy. Android 15 + One UI 7. Батарея 4 900 мАч, 25 Вт. IP68, Gorilla Glass Victus 2. Ни копейки не ушло на дело. Параллельная ветка. | U17: =HYPERLINK("#'Личные дела'!A17","открыть ▸") | W17: =IF(AND($N17>0,NOT(ISNUMBER(SEARCH("Отказ владельца",$Q17)))),$N17,"") | AL17: =IF(ISNUMBER(SEARCH("Отказ владельца",$Q17)),"ОТКАЗ","ОК")
A18: 10 | B18: iPhone 17 Pro Max | C18: Ушли и прочие | D18: 2026 | E18: 2026 | F18: 256 | G18: 12 | N18: 138020 | O18: 138 020 ₽ | P18: 256 ГБ, ОЗУ 12 ГБ | Q18: Продан ради съёмного дома | R18: Cosmic Orange | S18: WB | T18: iOS 26, nano-SIM + eSIM. IP68, гарантия 12 мес. Без предустановленного российского ПО. Ни копейки не ушло на дело. Параллельная ветка. | U18: =HYPERLINK("#'Личные дела'!A18","открыть ▸") | W18: =IF(AND($N18>0,NOT(ISNUMBER(SEARCH("Отказ владельца",$Q18)))),$N18,"") | AM18: =IF(ISNUMBER(SEARCH("Отказ владельца",$Q18)),"ОТКАЗ","ОК")
A19: 11 | B19: Soyes F8 Pro Max | C19: Ушли и прочие | D19: 2026 | E19: 2026 | F19: 16 | G19: 1 | H19: 3 | J19: 2000 | K19: 2 | L19: 1.3 | N19: 2500 | O19: 2 500 ₽ | P19: 16 ГБ + microSD до 64 ГБ, ОЗУ 1 ГБ | Q19: Бартер за наушники | R19: Black | S19: WB | T19: 3,0" IPS (480×854). 2 МП + 0,3 МП камеры. MTK6580M 1,3 ГГц. Android 8.1. Батарея 2 000 мАч. Размеры: 89,65×45,8×12 мм. Обмен. | U19: =HYPERLINK("#'Личные дела'!A19","открыть ▸") | W19: =IF(AND($N19>0,NOT(ISNUMBER(SEARCH("Отказ владельца",$Q19)))),$N19,"") | AN19: =IF(ISNUMBER(SEARCH("Отказ владельца",$Q19)),"ОТКАЗ","ОК")
A20: 12 | B20: Nokia 6300 (Silver) | C20: На службе | D20: 2026 | E20: 2026 | H20: 2 | K20: 2 | N20: 2000 | O20: 2 000 ₽ | P20: microSD до 2 ГБ | Q20: Кнопочный резерв | R20: Silver | S20: WB | T20: 2" TFT (240×320), 2 МП камера. 1 SIM (micro-SIM). 2G/3G (Tele2 не работает). Гарантия 1 неделя. Реплика, не оригинал HMD. Круг замкнулся. | U20: =HYPERLINK("#'Личные дела'!A20","открыть ▸") | W20: =IF(AND($N20>0,NOT(ISNUMBER(SEARCH("Отказ владельца",$Q20)))),$N20,"") | AO20: =IF(ISNUMBER(SEARCH("Отказ владельца",$Q20)),"ОТКАЗ","ОК")
A21: 13 | B21: Realme C75 | C21: Ушли и прочие | D21: 2026 | E21: 2026 | F21: 256 | G21: 8 | H21: 6.72 | I21: 90 | J21: 6000 | K21: 50 | M21: 45 | N21: 0 | O21: найден бесплатно | P21: 128/256 ГБ + microSD до 2 ТБ, ОЗУ 8 ГБ | Q21: Найден убитым | R21: Storm Black | S21: — | T21: 6,72" IPS (2400×1080), 90 Гц, стекло ArmorShell. 50 МП, фронт. 8 МП. Helio G92 Max. Android 14, realme UI 5.0. Батарея 6 000 мАч, 45 Вт. IP69. Экран отслаивается, разъёмы SIM повреждены. Заряд идёт. Найден до заказа Poco и BQ. | U21: =HYPERLINK("#'Личные дела'!A21","открыть ▸") | W21: =IF(AND($N21>0,NOT(ISNUMBER(SEARCH("Отказ владельца",$Q21)))),$N21,"") | AP21: =IF(ISNUMBER(SEARCH("Отказ владельца",$Q21)),"ОТКАЗ","ОК")
A22: 14 | B22: POCO F9 Ultra | C22: На службе | D22: 2026 | E22: 2026 | F22: 512 | H22: 6.9 | I22: 185 | J22: 8050 | K22: 200 | M22: 100 | N22: 97771 | O22: 97 771 ₽ | P22: 512 ГБ, UFS 4.1, ОЗУ 12/16 ГБ LPDDR5X | Q22: Король — Основной | R22: Black | S22: WB | T22: 6,9" AMOLED (2608×1200), 185 Гц, до 10 000 нит. 200 МП (OIS) + 50 МП перископ (5×) + 50 МП ширик, фронт. 32 МП. Snapdragon 8 Elite Gen 5. Android 16, HyperOS 3. Батарея 8 050 мАч, 100 Вт проводная, 50 Вт беспроводная. 5G, Wi-Fi 7, Bluetooth 6.0. IP68. Стерео Bose + сабвуфер, Dolby Atmos. Финальный босс. | U22: =HYPERLINK("#'Личные дела'!A22","открыть ▸") | W22: =IF(AND($N22>0,NOT(ISNUMBER(SEARCH("Отказ владельца",$Q22)))),$N22,"") | AQ22: =IF(ISNUMBER(SEARCH("Отказ владельца",$Q22)),"ОТКАЗ","ОК")
A23: 14.1 | B23: HOCO X50 | C23: Ушли и прочие | D23: 2026 | E23: 2026 | M23: 100 | N23: 382 | O23: 382 ₽ | P23: — (память не хранит) | Q23: Отменён — отказ владельца | R23: Black | S23: WB (каталог 237491773) | T23: Кабель Type-C → Type-C, 1 м, ток 5 А / до 100 Вт, чип E-marker — открывает полную проводную зарядку F9 Ultra (100 Вт, 20 В / 5 А). Первая подтехника Короля: 1) раскрыть 100-ваттную зарядку; 2) «фургон для переезда» — перенос ~100 ГБ с Hot 30 Play (№ 8) по кабелю USB-C → USB-C. 03.10.2026: фургон приступил к работе — Король получен, переезд начался. Первый фирменный кабель фонда после урока BQ Strike (№ 4). Выбрана 5-амперная версия за 382 ₽ вместо 3-амперной за 306 ₽. · 16.10.2026: статус исправлен — отказ владельца · 17.10.2026: ОТМЕНЁН владельцем — кабель дублирует комплектный Type-C→Type-C 100 Вт POCO F9 Ultra; зарядка и перенос данных закрыты комплектом | U23: =HYPERLINK("#'Личные дела'!A23","открыть ▸") | V23: ОТМЕНЁН | W23: =IF(AND($N23>0,NOT(ISNUMBER(SEARCH("Отказ владельца",$Q23)))),$N23,"") | AR23: =IF(ISNUMBER(SEARCH("Отказ владельца",$Q23)),"ОТКАЗ","ОК")
A24: 14.2 | B24: Xiaomi 120W HyperCharge (сетевое ЗУ) | C24: Ушли и прочие | D24: 2026 | E24: 2026 | M24: 120 | N24: 4575 | O24: 4 575 ₽ | P24: — (память не хранит) | Q24: Отменён — отказ владельца | R24: — | S24: WB (каталог 822768509) | T24: Фирменный сетевой адаптер Xiaomi 120W HyperCharge, глобальная версия, порт Type-C. Сердце системы питания Короля: паспортные 120 Вт, F9 Ultra возьмёт свои 100 Вт — 0→100% примерно за полчаса. Вместе с кабелем HOCO X50 (№ 14.1) образует полный комплект быстрой зарядки: блок + провод. Вторая подтехника Короля. · 16.10.2026: статус исправлен — отказ владельца · 17.10.2026: ОТМЕНЁН владельцем — блок HyperCharge уже в комплекте POCO F9 Ultra; питание закрыто повербанком 212 Вт (№ 14.3) | U24: =HYPERLINK("#'Личные дела'!A24","открыть ▸") | V24: ОТМЕНЁН | W24: =IF(AND($N24>0,NOT(ISNUMBER(SEARCH("Отказ владельца",$Q24)))),$N24,"") | AS24: =IF(ISNUMBER(SEARCH("Отказ владельца",$Q24)),"ОТКАЗ","ОК")
A25: 14A | B25: OnePlus 15 (CPH2749) | C25: Альтернативная ветка | D25: 2026 | E25: 2026 | F25: 256 | G25: 12 | J25: 7300 | M25: 120 | N25: 94761 | O25: 94 761 ₽ | P25: 256 ГБ, ОЗУ 12 ГБ | Q25: Альтернативная ветка | R25: Black | S25: WB (каталог 992924240) | T25: «Брат-близнец» Короля по производительности: тот же Snapdragon 8 Elite Gen 5, 12 ГБ ОЗУ. Отличия: 256 ГБ вместо 512 ГБ, OxygenOS 16 вместо HyperOS 3, 7 300 мАч / 120 Вт вместо 8 050 мАч / 100 Вт, eSIM (US-версия). Не заказан — Король (№ 14) уже оплачен и в пути. Резервная ветка: вступила бы в силу только в случае ухода F9 Ultra в мир павших смартфонов. | U25: =HYPERLINK("#'Личные дела'!A25","открыть ▸") | W25: =IF(AND($N25>0,NOT(ISNUMBER(SEARCH("Отказ владельца",$Q25)))),$N25,"") | AT25: =IF(ISNUMBER(SEARCH("Отказ владельца",$Q25)),"ОТКАЗ","ОК")
A26: 15 | B26: BQ 2430L Tank Connect | C26: Ушли и прочие | D26: 2026 | E26: 2026 | F26: 0.032 | H26: 2.4 | J26: 4000 | N26: 5105 | O26: 5 105 ₽ | P26: 32 МБ + microSD | Q26: Отказ владельца — отменён в пользу Pad 7 | R26: Black+Gunmetal | S26: WB | T26: 2,4" (240×320), 2 nano-SIM, 4G, USB-C. Режим Wi-Fi роутера, 2 фонарика. Батарея ~4 000 мАч. Комплектация: телефон, ЗУ, руководство. Гарантия 1 год. 4G-роутер + пауэрбанк. 27.09.2026: BQ ОТМЕНЁН в пользу Xiaomi Pad 7 (дело № 17). · 16.10.2026: статус исправлен — отказ владельца | U26: =HYPERLINK("#'Личные дела'!A26","открыть ▸") | V26: ОТМЕНЁН | W26: =IF(AND($N26>0,NOT(ISNUMBER(SEARCH("Отказ владельца",$Q26)))),$N26,"") | AU26: =IF(ISNUMBER(SEARCH("Отказ владельца",$Q26)),"ОТКАЗ","ОК")
A27: 16 | B27: POCO Pad M1 | C27: Ушли и прочие | D27: 2026 | E27: 2026 | F27: 256 | G27: 8 | H27: 12.1 | I27: 120 | J27: 12000 | M27: 33 | N27: 34614 | O27: 34 614 ₽ | P27: 256 ГБ UFS 2.2 + microSD до 2 ТБ, ОЗУ 8 ГБ LPDDR4X | Q27: Отказ владельца — отменён до получения | R27: Grey | S27: WB | T27: 12,1" IPS 2.5K (2560×1600), 120 Гц, 600 нит. Snapdragon 7s Gen 4 (4 нм), Adreno 810. Android 15, HyperOS 2. Батарея 12 000 мАч, 33 Вт. Wi-Fi 6, BT 5.4. 4 динамика, Dolby Atmos, 3,5 мм. Алюминий, 610 г. Без SIM, без NFC. Big Poco Brother — стационарная база. 27.09.2026: НАШЁЛ ПЛАНШЕТ ЛУЧШЕ — Xiaomi Pad 7 (дело № 17); заказ отменён до получения, средства возвращаются на WB Кошелёк. 28.09.2026: возврат 34 614 ₽ получен на карту ВТБ. Дело закрыто окончательно. · 16.10.2026: статус исправлен — отказ владельца | U27: =HYPERLINK("#'Личные дела'!A27","открыть ▸") | V27: ОТМЕНЁН | W27: =IF(AND($N27>0,NOT(ISNUMBER(SEARCH("Отказ владельца",$Q27)))),$N27,"") | AV27: =IF(ISNUMBER(SEARCH("Отказ владельца",$Q27)),"ОТКАЗ","ОК")
A28: 16.1 | B28: GEMBIRD KBW-8460 | C28: Ушли и прочие | D28: 2026 | E28: 2026 | N28: 1751 | O28: 1 751 ₽ | P28: — (память не хранит) | Q28: Отказ владельца | R28: Black | S28: WB | T28: Полноразмерная 108 клавиш (цифровой блок), низкопрофильный ножничный механизм, ход ~3 мм. Bluetooth 5.0 + USB Type-C, встроенный аккумулятор. Рус/англ раскладка. Совместимость: Android, Windows, iOS, macOS, Linux. Корпус: металл + пластик, 455 г. Без подсветки, KRO 6 клавиш, радиус BT ~1,5 м. Подтехника к Pad 7 — приданное нового стационарного устройства. 28.09.2026: ЗАКРЫТО. Устройство никогда не было на руках — весь цикл прошёл в статусе «Оформлен, сборка, в пути». Планшетная ветка свёрнута, переоформление невозможно — нет носителя. · 16.10.2026: статус исправлен — отказ владельца | U28: =HYPERLINK("#'Личные дела'!A28","открыть ▸") | V28: ОТМЕНЁН | W28: =IF(AND($N28>0,NOT(ISNUMBER(SEARCH("Отказ владельца",$Q28)))),$N28,"") | AW28: =IF(ISNUMBER(SEARCH("Отказ владельца",$Q28)),"ОТКАЗ","ОК")
A29: 16.2 | B29: Redragon Storm Basic | C29: Ушли и прочие | D29: 2026 | E29: 2026 | I29: 1000 | N29: 1737 | O29: 1 737 ₽ | P29: — (память не хранит) | Q29: Отказ владельца | R29: Black | S29: WB | T29: Проводная игровая мышь, USB, кабель 1,8 м в тканевой оплетке. Сенсор Pixart P3327, 200–12400 dpi, 1000 Гц, 30 G, 220 IPS. 5 кнопок + колесо-кнопка, переключатели Huano, ресурс 10 млн кликов. 90 г, 127×66×41 мм. Тефлоновые ножки, редактор макросов. Первая игровая периферия в фонде. Подтехника к Pad 7. 28.09.2026: ЗАКРЫТО. Устройство никогда не было на руках — весь цикл прошёл в статусе «Оформлен, сборка, в пути». Планшетная ветка свёрнута, переоформление невозможно — нет носителя. · 16.10.2026: статус исправлен — отказ владельца | U29: =HYPERLINK("#'Личные дела'!A29","открыть ▸") | V29: ОТМЕНЁН | W29: =IF(AND($N29>0,NOT(ISNUMBER(SEARCH("Отказ владельца",$Q29)))),$N29,"") | AX29: =IF(ISNUMBER(SEARCH("Отказ владельца",$Q29)),"ОТКАЗ","ОК")
A30: 16.3 | B30: WALKER OTG Type-C → USB | C30: Ушли и прочие | D30: 2026 | E30: 2026 | N30: 473 | O30: 473 ₽ | P30: — (память не хранит) | Q30: Отказ владельца | R30: Black | S30: WB | T30: Переходник Type-C (штекер) → USB (гнездо), OTG. Бренд WALKER, производство Китай. Проводник: медь + алюминий, 16 пар. Оболочка: PVC. Совместимость: ноутбук, смартфон, планшет, фото- и видеотехника. Гарантия 12 мес. Вес 5 г, размер 1,7×3 см. Связующее звено: проводная мышь Redragon подключается к порту Type-C планшета Pad 7 именно через этот переходник. Подтехника к Pad 7. 28.09.2026: ЗАКРЫТО. Устройство никогда не было на руках — весь цикл прошёл в статусе «Оформлен, сборка, в пути». Планшетная ветка свёрнута, переоформление невозможно — нет носителя. · 16.10.2026: статус исправлен — отказ владельца | U30: =HYPERLINK("#'Личные дела'!A30","открыть ▸") | V30: ОТМЕНЁН | W30: =IF(AND($N30>0,NOT(ISNUMBER(SEARCH("Отказ владельца",$Q30)))),$N30,"") | AY30: =IF(ISNUMBER(SEARCH("Отказ владельца",$Q30)),"ОТКАЗ","ОК")
A31: 17 | B31: Xiaomi Pad 7 | C31: Ушли и прочие | D31: 2026 | E31: 2026 | F31: 256 | G31: 12 | H31: 11.2 | I31: 144 | J31: 8850 | M31: 45 | N31: 36000 | O31: ~36 000 ₽ (12/256, Blue) | P31: 256 ГБ UFS 4.0, ОЗУ 12 ГБ LPDDR5X | Q31: ЗАКРЫТО | R31: Blue | S31: WB (каталог 1195323120) | T31: 11,2" IPS 3.2K (3200×2136), 144 Гц. Snapdragon 7+ Gen 3 (4 нм), Adreno 732, ~1,37 млн AnTuTu. Android 15, HyperOS 2. Батарея 8850 мАч, зарядка 45 Вт. Wi-Fi 6E, BT 5.2. 4 динамика, Dolby Atmos. Металлический корпус, ~500 г. Без SIM, без NFC. Преемник Pad M1: на ~55–60% быстрее в синтетике, +4 ГБ ОЗУ, UFS 4.0 вместо UFS 2.2, 144 Гц вместо 120 Гц. Целевые нагрузки: Geometry Dash с Geode (50–100 модов), Minecraft с шейдерами, GoreBox. Ожидает возврата средств за Pad M1 (на момент записи на WB оставалось 4 экз.). 28.09.2026: ЗАКРЫТО. «Условия не позволяют обеспечить им достойную мощность». Основная зарядка — от генератора, а не от городского электричества. Планшетная ветка свёрнута. Возврат к теме — 2030. | U31: =HYPERLINK("#'Личные дела'!A31","открыть ▸") | V31: ОТМЕНЁН | W31: =IF(AND($N31>0,NOT(ISNUMBER(SEARCH("Отказ владельца",$Q31)))),$N31,"") | AZ31: =IF(ISNUMBER(SEARCH("Отказ владельца",$Q31)),"ОТКАЗ","ОК")
A32: 18 | B32: Philips Xenium X175 | C32: На службе | D32: 2026 | E32: 2026 | N32: 2590 | O32: 2 590 ₽ | P32: — | Q32: Запасной оператор связи на тяжёлые времена | R32: Black | S32: WB (каталог 1055454807) | T32: Кнопочный мобильный телефон. Серия Xenium — традиция длинной автономности Philips. Брат-резерв к Nokia 6300 (№ 12) и наследник отменённого BQ Tank (№ 15).10.10.2026: получен — в один день с GT 30 Pro (№ 20). Включён: на экране 18:38, 10.10.2026, суббота — дата верна. SIM-карты не установлены — Xenium вежливо ждёт приписки. | U32: =HYPERLINK("#'Личные дела'!A32","открыть ▸") | W32: =IF(AND($N32>0,NOT(ISNUMBER(SEARCH("Отказ владельца",$Q32)))),$N32,"") | BA32: =IF(ISNUMBER(SEARCH("Отказ владельца",$Q32)),"ОТКАЗ","ОК")
A33: 19 | B33: Redmi Note 13 5G | C33: Ушли и прочие | D33: 2026 | E33: 2026 | F33: 256 | G33: 12 | H33: 6.67 | I33: 120 | J33: 5000 | K33: 108 | L33: 2.4 | M33: 33 | N33: 15473 | O33: 15 473 ₽ | P33: 256 ГБ UFS 2.2 + microSD до 1 ТБ, ОЗУ 12 ГБ | Q33: ВЫЧЕРКНУТ | R33: Black | S33: WB (каталог 1207714604) | T33: 6,67" AMOLED (1080×2400), 120 Гц, 1000 нит. 108 МП (OIS), фронт. 16 МП. MediaTek Dimensity 6080 (2×A76 2,4 ГГц + 6×A55 2,0 ГГц). Android 14, HyperOS 2. Батарея 5 000 мАч, 33 Вт. USB-C, NFC, стерео. Запасной рыцарь при Короле. Скачок эпох: A53→A76, eMMC→UFS 2.2, IPS→AMOLED, 16 МП→108 МП, 18 Вт→33 Вт, моно→стерео. | U33: =HYPERLINK("#'Личные дела'!A33","открыть ▸") | V33: ОТМЕНЁН | W33: =IF(AND($N33>0,NOT(ISNUMBER(SEARCH("Отказ владельца",$Q33)))),$N33,"") | BB33: =IF(ISNUMBER(SEARCH("Отказ владельца",$Q33)),"ОТКАЗ","ОК")
A34: 20 | B34: Infinix GT 30 Pro | C34: На службе | D34: 2026 | E34: 2026 | F34: 256 | G34: 12 | H34: 6.78 | I34: 144 | J34: 5500 | K34: 108 | L34: 3.35 | M34: 45 | N34: 35969 | O34: 35 969 ₽ | P34: 256 ГБ UFS 4.0, ОЗУ 12 ГБ LPDDR5X | Q34: Основной запасной — преемник Infinix Hot 30 Play | R34: Dark Flare | S34: WB (каталог 890339441) | T34: 6,78" AMOLED 1,5K (2720×1224), 144 Гц, 4500 нит. 108 МП + 8 МП ширик, фронт. 13 МП. MediaTek Dimensity 8350 Ultimate (4 нм, 1×A715 3,35 ГГц + 3×A715 3,2 ГГц + 4×A510 2,2 ГГц), Mali-G615 MC6. Android 15, XOS 15. Батарея 5 500 мАч, 45 Вт проводная, 30 Вт беспроводная. 5G, NFC, BT 5.4, IP64. GT-триггеры, LED-подсветка, bypass-зарядка, 3D Vapor Cloud Chamber (5400 мм²), стерео, ИК-порт. 188 г. AnTuTu ~1,3–1,75 млн. Первый Infinix без единого доисторического компонента. Эволюция завершена.10.10.2026: получен — в один день с Philips Xenium X175 (№ 18). Принял присягу: заводской стикер подтверждает Dimensity 8350, 144 Гц AMOLED, триггеры, 256+12 ГБ. Киберклинок материализован | U34: =HYPERLINK("#'Личные дела'!A34","открыть ▸") | W34: =IF(AND($N34>0,NOT(ISNUMBER(SEARCH("Отказ владельца",$Q34)))),$N34,"") | BC34: =IF(ISNUMBER(SEARCH("Отказ владельца",$Q34)),"ОТКАЗ","ОК")
A35: 14.3 | B35: Xiaomi HyperCharge Power Bank 25000 (212 Вт) | C35: Подтехники | D35: 2026 | E35: 2026 | N35: 17963 | O35: 17 963 ₽ | P35: 25 000 мАч (90,8 Вт·ч), 2×USB-C + USB-A | Q35: Подтехника — на службе | R35: — | S35: WB | T35: Прозрачный корпус, цветной дисплей заряда. До 140 Вт с одного USB-C (PD 3.1), до 212 Вт суммарно на три порта; тянет ноутбуки и смартфоны. Номинальная ёмкость ~14 000 мАч. Единственная подтехника, оставленная владельцем (16.10.2026). Рынок: ~5 990 ₽ (CN-версия) — 11 490 ₽ (GL, BHR9970GL). Цена подтверждена владельцем 16.10.2026: 17 963 ₽ (архивная приписка «4000+» аннулирована). | W35: =IF(AND($N35>0,NOT(ISNUMBER(SEARCH("Отказ владельца",$Q35)))),$N35,"") | BD35: =IF(ISNUMBER(SEARCH("Отказ владельца",$Q35)),"ОТКАЗ","ОК")
A36: 21 | B36: TeXet TM-130 | C36: На службе | D36: 2019 | E36: 2025 | H36: 1.77 | J36: 600 | N36: 800 | O36: 800 ₽ | P36: 32 МБ + microSD до 32 ГБ | Q36: На службе | R36: Black | S36: Эльдорадо, Керчь | T36: 1,77" TFT-TN (128×160), 2G, 2 SIM. Без камеры и Bluetooth — «использование в условиях повышенной информационной безопасности». FM-радио, фонарик, диктофон. Батарея 600 мАч съёмная, Micro-USB. 110×47×14 мм, 65 г. Диптих «перед/задник» — фото автора. На службе (в другом городе). | W36: =IF(AND($N36>0,NOT(ISNUMBER(SEARCH("Отказ владельца",$Q36)))),$N36,"")

Sheet Исправления
A1: Время | B1: Устройство | C1: Было | D1: Стало | E1: Пояснение
A2: 19:58 | B2: Samsung Galaxy Mini 2 | C2: цвет не указан | D2: Yellow (официальное название цвета)
A3: 19:59 | B3: Lenovo (телефон) | C3: цвет не указан | D3: Black; добавлено уточнение «небольшой»
A4: 20:00 | B4: Infinix Hot 12 Pro | C4: Чёрный | D4: Electric Blue (глянцево-голубой)
A5: 20:00 | B5: P901 | C5: Серый/Чёрный | D5: White
A6: 20:01 | B6: Samsung S25+ | C6: Серый/Чёрный | D6: Silver Shadow
A7: 20:01 | B7: POCO F9 Ultra | C7: Серый/Чёрный | D7: Black
A8: 20:02 | B8: Infinix Hot 11 | C8: Чёрный | D8: Polar Black
A9: 20:02 | B9: Infinix Hot 30 Play | C9: Чёрный | D9: Black (официальное)
A10: 20:03 | B10: BQ-5035 Velvet | C10: Бежевый | D10: Gold (официальное; бежевым запомнился владельцу)
A11: 20:03 | B11: iPhone 17 Pro Max | C11: Оранжевый | D11: Cosmic Orange
A12: 20:04 | B12: Realme C75 | C12: Тёмный | D12: Storm Black
A13: 20:04 | B13: BQ 2430L Tank Connect | C13: Чёрный | D13: Black+Gunmetal
... A93: 15:48 | B93: Издание — ширина листов и названия | C93: Титульный лист 800 px, реестр 900 px; длинные наименования выезжали за грань на узком экране | D93: 15.10.2026, Ильинка: листы расширены до 960 px, включён перенос длинных слов; в оглавлении длинные наименования скрыты за кнопкой «Показать полные названия»
A94: 16:24 | B94: Вёрстка | C94: overflow-wrap: break-word; word-break: normal | D94: overflow-wrap: break-word; таблицам — прокрутка на мобильном | E94: Устранено сжатие колонок до одной буквы (скриншоты 15:55 и 16:17): свойство anywhere уменьшало минимальную ширину колонок таблиц. Заменено на break-word — слова переносятся только целиком, когда не влезают.
A95: 16:31 | B95: Стили | C95: opacity: 0.5 (4 карточки), opacity: 0.85 (.card-id) | D95: все значения opacity изъяты из издания | E95: Приглушение снято полностью: реестр и карточки читаются полными чернилами. Статус «ушёл» передаётся только зачёркиванием.
A96: 16:56 | B96: Модернизация | C96: поиск и фильтры отсутствуют | D96: поисково-фильтровальный комплекс | E96: Строка поиска (по названиям, скрытым расширениям и заметкам) + 8 фильтров статуса со счётчиком найденного. Работает на оглавлении и реестре одновременно.
A97: 17:20 | B97: Модернизация II — сортировка реестра | C97: реестр — только хронологический порядок | D97: сортировка по 10 параметрам в обе стороны | E97: Параметры: № дела, год, цена, ПЗУ, ОЗУ, диагональ экрана, батарея, камера, частота процессора, мощность зарядки. Кнопка ↓/↑ меняет направление; старт по умолчанию — по убыванию (год — новее сверху, числа — больше сверху). Строки без данных уходят в конец списка. Сортировка не отменяет поиск и фильтры.
A98: 17:40 | B98: Модель — опознание | C98: Infinix Hot 12 Pro (запись по внешнему сходству) | D98: Infinix Hot 20i (X665E) | E98: Истина установлена через GT 30 Pro (№ 20, раздел «Связанные устройства») и сверку спецификаций (4PDA, iXBT, DNS). Модели внешне схожи — одинаковый экран 6,6" (1612×720) — но железо иное: Helio G25 вместо Tiger T616, камера 13 МП вместо 50, micro-USB и 10 Вт вместо USB-C и 18 Вт, без NFC. Цвет переименован в Luna Blue (официальное название), добавлен год модели — 2022. Счётчик записей: 32→34
A99: 17:57 | B99: Дело № 6 — археологический разбор | C99: — | D99: разбор «Палеолит под чужим именем» | E99: 10 компонентов расставлены по эпохам: порт, зарядка и NFC — палеолит; Helio G25 и камера 13 МП — доисторическая эра; экран 60 Гц — средневековье; ОЗУ и накопитель — древний мир и позднее средневековье (до выяснения точной конфигурации); Android 12 и батарея 5 000 мАч — вне подозрений.
A100: 16.10.2026 | B100: Реестр, № 15, № 16, 14.1, 14.2, 16.1–16.3 | C100: № 15, № 16 — «В пути»; подтехники — 5, категория «Подтехники» | D100: «Отказ владельца» (7 записей), категория «Ушли и прочие»; подтехники — 1 (№ 14.3 повербанк); «В пути» упразднена (0) | E100: Владелец подтвердил отказы 16.10.2026; заказы № 15/№ 16 отменены ещё 27–28.09.2026 (средства возвращены на WB Кошелёк — см. заметки дел). Сумма покупок фонда: 729 034 → 680 397 ₽.
A101: 16.10.2026 | B101: Реестр, № 14.3 (повербанк) | C101: Цена не зафиксирована; в предыдущей выдаче ошибочно фигурировала «4000+» | D101: 17 963 ₽ | E101: Цена подтверждена владельцем 16.10.2026. Сумма покупок фонда пересчитана живой формулой: 680 397 → 698 360 ₽ (ранее ошибочно указывалось 694 360 — арифметика исправлена).
A102: 16.10.2026 11:30 | B102: Фонд целиком (v4.1) | C102: Мобильная редакция: умная таблица + Флаг, карточки и вертикальные рекордсмены в Статистике, заголовку задана высота (антитонущий), графики с явно вписанными подписями (против мобильного «Вече»), обложка пересобрана, CJK-символы вычищены
A103: 16.10.2026 11:35 | B103: Вкладка Графики | C103: Три чертежа с явными подписями (v4.2) | D103: Исправлен namespace a: в chartSpace; мобильный рендер всё равно захлебнулся
A104: 16.10.2026 11:45 | B104: Вкладка Графики | C104: Чертежи (DrawingML) — несовместимы с мобильным рендером | D104: Вкладка упразднена: заменена текст-графиками REPT на Статистике (v4.3)
A105: 16.10.2026 17:50 | B105: Sony Xperia Z1 (дело № 2c) | C105: Опознание: Sony Xperia 1 (J9110), 2018–2019 | D105: Переприписка по памяти владельца: Sony Xperia Z1 (C6903), модель 2013 года (OmniBalance, кнопка спуска, заглушки IP55/IP58), приход 2018 подтверждён — задолго до выпуска J9110 (2019). Цена покупки снята: дар (вероятно, от отца); справочно старт 2013 — ~29 990 ₽. Восстановление: 3 000–8 000 ₽. В график батарей добавлена строка 2013 · 3 000 мАч. История прежних записей нетронута (v4.4)
A106: 16.10.2026 20:35 | B106: Soyes F8 Pro Max (дело № 11) | C106: Написание «Seyes» по всему фонду | D106: Амнистия имён: повсеместная замена на «Soyes» — исторически верное написание бренда (карточка товара оригинала). Замена выполнена в презентации (v25.1), издании и настоящем реестре, включая исторические записи. В настоящей записи прежнее написание сохранено намеренно
A107: 16.10.2026 20:50 | B107: TeXet TM-130 (дело № 21) | C107: Новый приход | D107: Приход № 21: TeXet TM-130, кнопочный, 800 ₽, «Эльдорадо», Керчь, июль 2025. Статус: на службе (в другом городе). Диптих «перед/задник», источник фото — автор. Внесён во все три носителя (v25.2 / v4.6 / издание).
A108: 16.10.2026 23:05 | B108: Статистика · Хронология (v4.7) | C108: График батарей: 22 строки — без TeXet (2019); подписи — только год; Хронология 2025 — без № 21 | D108: График батарей пересобран из реестра: 23 строки, добавлен TeXet TM-130 (2019 · 600 мАч); подписи — формат «год · устройство» формулой; Хронология 2025 дополнена: № 21 · TeXet TM-130 (приход 07.2025). Проверено: Флаг отказных — живая формула (искажений нет)
A109: 17.10.2026 05:56 | B109: Ночная ревизия (издание + реестр) | C109: № 17 «Статус не присвоен»; ночные corr-записи без дат; огрызки эмодзи в статусах № 8/№ 20; ПЗУ/ОЗУ 0a/0b/0c в долях ГБ | D109: № 17 → ЗАКРЫТО (corr 05:45: дело закрыто 28.09 — «условия не позволяют обеспечить мощность»); corr-записи издания датированы 17.10.2026; огрызки U+FE0F удалены; память: 0a «2 МБ», 0b «10/16 МБ», 0c «7,8 МБ»
A110: 17.10.2026 05:58 | B110: Xiaomi 120W HyperCharge (дело № 14.2) | C110: Подтехника · статус «Отказ владельца» | D110: ОТМЕНЁН владельцем: блок HyperCharge уже в комплекте POCO F9 Ultra, питание закрыто повербанком 212 Вт (№ 14.3). Зачёркнут во всех носителях. Сумма фонда без изменений — исключён из неё как отказной с 16.10
A111: 17.10.2026 06:06 | B111: HOCO X50 (дело № 14.1) | C111: Подтехника · статус «Отказ владельца» | D111: ОТМЕНЁН владельцем: кабель дублирует комплектный Type-C→Type-C 100 Вт POCO F9 Ultra. Зачёркнут во всех носителях. Сумма фонда без изменений — исключён из неё как отказной с 16.10
A112: 17.10.2026 06:15 | B112: Excel v4.7 → v4.8 | C112: Консолидация ночных правок | D112: Внесены: отмена № 14.1/14.2 (статус «Отменён — отказ владельца», шрифт зачёркнут), № 17 → ЗАКРЫТО, огрызки эмодзи удалены, МБ-хвосты заменены. Формулы статистики (100 шт., поиск «Отказ владельца») сохранены живыми — составной статус не ломает счётчики: экспонатов 28, отказных 7
A113: 17.10.2026 · 06:32 | B113: Все носители | C113: — | D113: красная печать «ОТМЕНЁН» | E113: Диагональ во весь рост в реестре и личных делах издания (7+7), ровный штамп в оглавлении и атласе, красный флаг в Excel, штамп на слайде отказов ПВ38. Печать стоит на № 14.1, 14.2, 15, 16, 16.1–16.3.
A114: 17.10.2026 · 07:09 | B114: Excel v4.8 · печать | C114: Флаг «ОТМЕНЁН» установлен для № 17 (Xiaomi Pad 7) и № 19 (Redmi Note 13 5G) — итого 9 штампов в колонке Флаг; статус № 17 «ЗАКРЫТО» сохранён

Sheet Личные дела
A1: № | B1: Название дела | C1: Категория | D1: → Реестр
A2: 0a | B2: Samsung SGH-C130 | C2: Археология | D2: =HYPERLINK("#Реестр!A2","открыть ▸")
A3: 0b | B3: Samsung E250 | C3: Археология | D3: =HYPERLINK("#Реестр!A3","открыть ▸")
A4: 0c | B4: Nokia 6300 | C4: Археология | D4: =HYPERLINK("#Реестр!A4","открыть ▸")
A5: 0d | B5: Безымянные кнопочные | C5: Археология | D5: =HYPERLINK("#Реестр!A5","открыть ▸")
A6: 1 | B6: Samsung Galaxy Mini 2 | C6: Археология | D6: =HYPERLINK("#Реестр!A6","открыть ▸")
A7: 2 | B7: Lenovo A328 | C7: Ушли и прочие | D7: =HYPERLINK("#Реестр!A7","открыть ▸")
A8: 2b | B8: Lenovo Tab 2 A10-70L | C8: Ушли и прочие | D8: =HYPERLINK("#Реестр!A8","открыть ▸")
A9: 2c | B9: Sony Xperia Z1 (C6903) | C9: Ушли и прочие | D9: =HYPERLINK("#Реестр!A9","открыть ▸")
A10: 3 | B10: BQ-5035 Velvet | C10: Ушли и прочие | D10: =HYPERLINK("#Реестр!A10","открыть ▸")
A11: 4 | B11: BQ Strike | C11: Ушли и прочие | D11: =HYPERLINK("#Реестр!A11","открыть ▸")
A12: 5 | B12: Infinix Hot 11 | C12: Ушли и прочие | D12: =HYPERLINK("#Реестр!A12","открыть ▸")
A13: 6 | B13: Infinix Hot 20i (X665E) | C13: Ветераны | D13: =HYPERLINK("#Реестр!A13","открыть ▸")
A14: 6b | B14: Honor X7c | C14: Ушли и прочие | D14: =HYPERLINK("#Реестр!A14","открыть ▸")
A15: 7 | B15: P901 (OPPO CPH1821EX) | C15: Ушли и прочие | D15: =HYPERLINK("#Реестр!A15","открыть ▸")
A16: 8 | B16: Infinix Hot 30 Play | C16: Ветераны | D16: =HYPERLINK("#Реестр!A16","открыть ▸")
A17: 9 | B17: Samsung S25+ | C17: Ушли и прочие | D17: =HYPERLINK("#Реестр!A17","открыть ▸")
A18: 10 | B18: iPhone 17 Pro Max | C18: Ушли и прочие | D18: =HYPERLINK("#Реестр!A18","открыть ▸")
A19: 11 | B19: Soyes F8 Pro Max | C19: Ушли и прочие | D19: =HYPERLINK("#Реестр!A19","открыть ▸")
A20: 12 | B20: Nokia 6300 (Silver) | C20: На службе | D20: =HYPERLINK("#Реестр!A20","открыть ▸")
A21: 13 | B21: Realme C75 | C21: Ушли и прочие | D21: =HYPERLINK("#Реестр!A21","открыть ▸")
A22: 14 | B22: POCO F9 Ultra | C22: На службе | D22: =HYPERLINK("#Реестр!A22","открыть ▸")
A23: 14.1 | B23: HOCO X50 | C23: Подтехники | D23: =HYPERLINK("#Реестр!A23","открыть ▸")
A24: 14.2 | B24: Xiaomi 120W HyperCharge (сетевое ЗУ) | C24: Подтехники | D24: =HYPERLINK("#Реестр!A24","открыть ▸")
A25: 14A | B25: OnePlus 15 (CPH2749) | C25: Альтернативная ветка | D25: =HYPERLINK("#Реестр!A25","открыть ▸")
A26: 15 | B26: BQ 2430L Tank Connect | C26: В пути | D26: =HYPERLINK("#Реестр!A26","открыть ▸")
A27: 16 | B27: POCO Pad M1 | C27: В пути | D27: =HYPERLINK("#Реестр!A27","открыть ▸")
A28: 16.1 | B28: GEMBIRD KBW-8460 | C28: Подтехники | D28: =HYPERLINK("#Реестр!A28","открыть ▸")
A29: 16.2 | B29: Redragon Storm Basic | C29: Подтехники | D29: =HYPERLINK("#Реестр!A29","открыть ▸")
A30: 16.3 | B30: WALKER OTG Type-C → USB | C30: Подтехники | D30: =HYPERLINK("#Реестр!A30","открыть ▸")
A31: 17 | B31: Xiaomi Pad 7 | C31: Ушли и прочие | D31: =HYPERLINK("#Реестр!A31","открыть ▸")
A32: 18 | B32: Philips Xenium X175 | C32: На службе | D32: =HYPERLINK("#Реестр!A32","открыть ▸")
A33: 19 | B33: Redmi Note 13 5G | C33: Ушли и прочие | D33: =HYPERLINK("#Реестр!A33","открыть ▸")
A34: 20 | B34: Infinix GT 30 Pro | C34: На службе | D34: =HYPERLINK("#Реестр!A34","открыть ▸")
A35: 21 | B35: TeXet TM-130 | C35: На службе | D35: =HYPERLINK("#Реестр!A36","открыть ▸")

Sheet Статистика
B2: ЖИВАЯ СТАТИСТИКА ФОНДА
B3: все цифры — живые формулы: правка реестра пересчитывает всё само
B5: =COUNTIFS(Реестр!$Q$2:$Q$36,"<>*Отказ владельца*") | D5: =COUNTIFS(Реестр!$Q$2:$Q$36,"<>*Отказ владельца*",Реестр!$N$2:$N$36,">0") | F5: =SUMIFS(Реестр!$N$2:$N$36,Реестр!$Q$2:$Q$36,"<>*Отказ владельца*") | H5: =ROUND(AVERAGEIFS(Реестр!$N$2:$N$36,Реестр!$Q$2:$Q$36,"<>*Отказ владельца*"),0)
B6: экспонатов | D6: куплено | F6: сумма покупок, ₽ | H6: средняя цена, ₽
B9: Общие счётчики
B10: Всего записей хроники | C10: =COUNTA(Реестр!$A$2:$A$36)
B11: Экспонатов (без отказных) | C11: =COUNTIFS(Реестр!$Q$2:$Q$36,"<>*Отказ владельца*")
B12: Куплено (цена > 0) | C12: =COUNTIFS(Реестр!$Q$2:$Q$36,"<>*Отказ владельца*",Реестр!$N$2:$N$36,">0")
B13: Найдено бесплатно (цена 0) | C13: =COUNTIFS(Реестр!$Q$2:$Q$36,"<>*Отказ владельца*",Реестр!$N$2:$N$36,0)
B15: Деньги
B16: Сумма покупок (без отказных), ₽ | C16: =SUMIFS(Реестр!$N$2:$N$36,Реестр!$Q$2:$Q$36,"<>*Отказ владельца*")
B17: Средняя цена покупки, ₽ | C17: =ROUND(AVERAGEIFS(Реестр!$N$2:$N$36,Реестр!$Q$2:$Q$36,"<>*Отказ владельца*",Реестр!$N$2:$N$36,">0"),0)
B18: Максимальная цена, ₽ | C18: =MAX(Реестр!$W$2:$W$36)
B19: Минимальная из купленных, ₽ | C19: =MIN(Реестр!$W$2:$W$36)
B21: Возраст фонда
B22: Средний год модели | C22: =ROUND(AVERAGEIFS(Реестр!$D$2:$D$36,Реестр!$Q$2:$Q$36,"<>*Отказ владельца*"),1)
B23: Средний возраст, лет | C23: =ROUND(2026-AVERAGEIFS(Реестр!$D$2:$D$36,Реестр!$Q$2:$Q$36,"<>*Отказ владельца*"),1)
B24: Старейший экспонат | C24: Samsung SGH-C130 (№ 0a) · модель 2007
B25: Новейший | C25: POCO F9 Ultra и другие · модель 2026
B27: Категории (живые счётчики, без отказных)
B28: На службе | C28: =COUNTIFS(Реестр!$C$2:$C$36,"На службе",Реестр!$Q$2:$Q$36,"<>*Отказ владельца*")
B29: Ветераны | C29: =COUNTIFS(Реестр!$C$2:$C$36,"Ветераны",Реестр!$Q$2:$Q$36,"<>*Отказ владельца*")
B30: Подтехники | C30: =COUNTIFS(Реестр!$C$2:$C$36,"Подтехники",Реестр!$Q$2:$Q$36,"<>*Отказ владельца*")
B31: Альтернативная ветка | C31: =COUNTIFS(Реестр!$C$2:$C$36,"Альтернативная ветка",Реестр!$Q$2:$Q$36,"<>*Отказ владельца*")
B32: Археология | C32: =COUNTIFS(Реестр!$C$2:$C$36,"Археология",Реестр!$Q$2:$Q$36,"<>*Отказ владельца*")
B33: Ушли и прочие | C33: =COUNTIFS(Реестр!$C$2:$C$36,"Ушли и прочие",Реестр!$Q$2:$Q$36,"<>*Отказ владельца*")
B34: В пути · упразднена 16.10.2026 | C34: 0
B36: Рекордсмены (снимок 16.10.2026)
B37: 1. Цена: iPhone 17 Pro Max — 138 020 ₽
B38: 2. Батарея: Xiaomi Pad 7 — 8 850 мАч
B39: 3. Камера: POCO F9 Ultra — 200 МП
B40: 4. Экран: Xiaomi Pad 7 — 11.2″
B41: 5. Зарядка: OnePlus 15 (CPH2749) — 120 Вт
B42: 6. ПЗУ 512 ГБ — ничья: Honor X7c, P901 (OPPO CPH1821EX), POCO F9 Ultra, Samsung S25+
B44: Пришло по годам (без отказных)
B45: 2007 | C45: =COUNTIFS(Реестр!$E$2:$E$36,2007,Реестр!$Q$2:$Q$36,"<>*Отказ владельца*")
B46: 2008 | C46: =COUNTIFS(Реестр!$E$2:$E$36,2008,Реестр!$Q$2:$Q$36,"<>*Отказ владельца*")
B47: 2009 | C47: =COUNTIFS(Реестр!$E$2:$E$36,2009,Реестр!$Q$2:$Q$36,"<>*Отказ владельца*")
B48: 2010 | C48: =COUNTIFS(Реестр!$E$2:$E$36,2010,Реестр!$Q$2:$Q$36,"<>*Отказ владельца*")
B49: 2011 | C49: =COUNTIFS(Реестр!$E$2:$E$36,2011,Реестр!$Q$2:$Q$36,"<>*Отказ владельца*")
...

Sheet Восстановление
A1: 🛠 ЛИСТ ВОССТАНОВЛЕНИЯ ФОНДА PH-2026
A2: Сколько бы стоило вернуть ушедших — по ценам рынка октября 2026. Коэффициент индексации редактируемый: поменяй — таблица пересчитается.
A4: Коэффициент индексации: | D4: 1 | E4: ← редактируй это значение (1,0 = цена приобретения без индексации)
A6: ID | B6: Устройство | C6: Обстоятельство утраты | D6: Цена приобр., ₽ | E6: Год прихода | F6: Оценка б/у мин, ₽ | G6: Оценка б/у макс, ₽ | H6: Средняя оценка, ₽ | I6: Индексированная, ₽ | J6: Вердикт | K6: → Реестр
A7: 2 | B7: Lenovo A328 | C7: Ушёл | D7: 4490 | E7: 2014 | F7: 500 | G7: 1200 | H7: =(F7+G7)/2 | I7: =D7*$D$4 | J7: Ушёл в добрые руки — вернуть можно, покупка б/у | K7: открыть ▸
A8: 2b | B8: Lenovo Tab 2 A10-70L | C8: Убит яростью | D8: 17990 | E8: 2015 | F8: 1500 | G8: 3000 | H8: =(F8+G8)/2 | I8: =D8*$D$4 | J8: Убит яростью: живой корпус найден, но с трещинами истории | K8: открыть ▸
A9: 2c | B9: Sony Xperia Z1 (C6903) | C9: Ушёл | E9: 2018 | F9: 3000 | G9: 8000 | H9: =(F9+G9)/2 | I9: =D9*$D$4 | J9: Восстановим: на рынке живые, от ломбарда до полного комплекта | K9: открыть ▸
A10: 3 | B10: BQ-5035 Velvet | C10: Бесследно утерян | D10: 4190 | E10: 2017 | F10: 500 | G10: 1200 | H10: =(F10+G10)/2 | I10: =D10*$D$4 | J10: Бесследно утерян — «Парк» молчит. Шансы исчезающи | K10: открыть ▸
A11: 4 | B11: BQ Strike | C11: Источник «грязного провода» | D11: 2500 | E11: 2016 | F11: 500 | G11: 1200 | H11: =(F11+G11)/2 | I11: =D11*$D$4 | J11: Источник «грязного провода»: сам ушёл — сам и виноват | K11: открыть ▸
A12: 5 | B12: Infinix Hot 11 | C12: Умер от грязного провода | D12: 11000 | E12: 2021 | F12: 5000 | G12: 6600 | H12: =(F12+G12)/2 | I12: =D12*$D$4 | J12: Умер от грязного провода — воскрешение возможно только б/у | K12: открыть ▸
A13: 6b | B13: Honor X7c | C13: Ушёл по невыгодному обмену | D13: 0 | E13: 2024 | F13: 6000 | G13: 9000 | H13: =(F13+G13)/2 | I13: =IF(D13="","",D13*$D$4) | J13: Ушёл по невыгодному обмену — обмен всё ещё невыгоден | K13: открыть ▸
A14: 7 | B14: P901 (OPPO CPH1821EX) | C14: Изгнан | D14: 6818 | E14: 2023 | F14: 2000 | G14: 3500 | H14: =(F14+G14)/2 | I14: =D14*$D$4 | J14: Изгнан — восстановить можно, но зачем | K14: открыть ▸
A15: 9 | B15: Samsung S25+ | C15: Продан ради съёмного дома | D15: 90000 | E15: 2026 | F15: 80000 | G15: 100000 | H15: =(F15+G15)/2 | I15: =D15*$D$4 | J15: Продан ради съёмного дома: восстановление дороже смысла | K15: открыть ▸
A16: 10 | B16: iPhone 17 Pro Max | C16: Продан ради съёмного дома | D16: 138020 | E16: 2026 | F16: 120000 | G16: 160000 | H16: =(F16+G16)/2 | I16: =D16*$D$4 | J16: Продан ради съёмного дома: восстановим только вместе с домом | K16: открыть ▸
A17: 11 | B17: Soyes F8 Pro Max | C17: Бартер за наушники | D17: 2500 | E17: 2026 | F17: 1500 | G17: 3000 | H17: =(F17+G17)/2 | I17: =D17*$D$4 | J17: Бартер за наушники: обратный обмен маловероятен | K17: открыть ▸
A18: 13 | B18: Realme C75 | C18: Найден убитым | D18: 0 | E18: 2026 | F18: 6000 | G18: 9000 | H18: =(F18+G18)/2 | I18: =D18*$D$4 | J18: Найден убитым, бесплатно. Второй раз бесплатно не найдётся | K18: открыть ▸
A19: 17 | B19: Xiaomi Pad 7 | C19: Статус не присвоен | D19: 36000 | E19: 2026 | F19: 25000 | G19: 32000 | H19: =(F19+G19)/2 | I19: =D19*$D$4 | J19: Статус не присвоен — восстановим, пока он окончательно не ушёл | K19: открыть ▸
A20: 19 | B20: Redmi Note 13 5G | C20: ВЫЧЕРКНУТ | D20: 15473 | E20: 2026 | F20: 8000 | G20: 12000 | H20: =(F20+G20)/2 | I20: =D20*$D$4 | J20: ВЫЧЕРКНУТ из хроники — но рынок его помнит | K20: открыть ▸
C21: ИТОГО по всем ушедшим | F21: =SUM(F7:F20) | G21: =SUM(G7:G20) | H21: =SUM(H7:H20) | I21: =SUM(I7:I20)
A23: Методика: 2 позиции сверены с живыми объявлениями (Авито, октябрь 2026) — Hot 11 4/128, Lenovo Tab 2 A10-70L; остальные — экспертная оценка по аналогам того же класса. № 2c (Xperia Z1) — сверка с живыми объявлениями не проводилась.
A24: Оценки — диапазон «мин–макс» по состоянию «рабочий, без критических дефектов». Средняя — база для бюджета восстановления.
A25: «Продан ради съёмного дома» — восстановление считается теоретически: добровольная утрата восполнима только кошельком.
A26: Лист построен 15.10.2026, 18:50 · Алиса AI · фонд PH-2026

Sheet Хронология
B2: ХРОНОЛОГИЯ ВЛАДЕНИЯ · 2007–2026
B3: приходы по годам · отказные заказы (7 записей) приходами не считаются
B4: Год | C4: Пришло | D4: Устройства
B5: 2007 | C5: =SUMPRODUCT((Реестр!$E$2:$E$36=B5)*(LEFT(Реестр!$Q$2:$Q$36&"",5)<>"Отказ")) | D5: № 0a · Samsung SGH-C130
B6: 2008 | C6: =SUMPRODUCT((Реестр!$E$2:$E$36=B6)*(LEFT(Реестр!$Q$2:$Q$36&"",5)<>"Отказ")) | D6: —
B7: 2009 | C7: =SUMPRODUCT((Реестр!$E$2:$E$36=B7)*(LEFT(Реестр!$Q$2:$Q$36&"",5)<>"Отказ")) | D7: —
B8: 2010 | C8: =SUMPRODUCT((Реестр!$E$2:$E$36=B8)*(LEFT(Реестр!$Q$2:$Q$36&"",5)<>"Отказ")) | D8: № 0b · Samsung E250; № 0c · Nokia 6300; № 0d · Безымянные кнопочные
B9: 2011 | C9: =SUMPRODUCT((Реестр!$E$2:$E$36=B9)*(LEFT(Реестр!$Q$2:$Q$36&"",5)<>"Отказ")) | D9: —
B10: 2012 | C10: =SUMPRODUCT((Реестр!$E$2:$E$36=B10)*(LEFT(Реестр!$Q$2:$Q$36&"",5)<>"Отказ")) | D10: № 1 · Samsung Galaxy Mini 2
B11: 2013 | C11: =SUMPRODUCT((Реестр!$E$2:$E$36=B11)*(LEFT(Реестр!$Q$2:$Q$36&"",5)<>"Отказ")) | D11: —
B12: 2014 | C12: =SUMPRODUCT((Реестр!$E$2:$E$36=B12)*(LEFT(Реестр!$Q$2:$Q$36&"",5)<>"Отказ")) | D12: № 2 · Lenovo A328
B13: 2015 | C13: =SUMPRODUCT((Реестр!$E$2:$E$36=B13)*(LEFT(Реестр!$Q$2:$Q$36&"",5)<>"Отказ")) | D13: № 2b · Lenovo Tab 2 A10-70L
B14: 2016 | C14: =SUMPRODUCT((Реестр!$E$2:$E$36=B14)*(LEFT(Реестр!$Q$2:$Q$36&"",5)<>"Отказ")) | D14: № 4 · BQ Strike
B15: 2017 | C15: =SUMPRODUCT((Реестр!$E$2:$E$36=B15)*(LEFT(Реестр!$Q$2:$Q$36&"",5)<>"Отказ")) | D15: № 3 · BQ-5035 Velvet
B16: 2018 | C16: =SUMPRODUCT((Реестр!$E$2:$E$36=B16)*(LEFT(Реестр!$Q$2:$Q$36&"",5)<>"Отказ")) | D16: № 2c · Sony Xperia Z1
... B24: 2026 | C24: =SUMPRODUCT((Реестр!$E$2:$E$36=B24)*(LEFT(Реестр!$Q$2:$Q$36&"",5)<>"Отказ")) | D24: № 9 · Samsung S25+; № 10 · iPhone 17 Pro Max; № 11 · Soyes F8 Pro Max; № 12 · Nokia 6300 (Silver); № 13 · Realme C75; № 14 · POCO F9 Ultra; № 14.3 · Xiaomi HyperCharge Power Bank 25000 (212 Вт); № 14A · OnePlus 15 (CPH2749); № 17 · Xiaomi Pad 7; № 18 · Philips Xenium X175; № 19 · Redmi Note 13 5G; № 20 · Infinix GT 30 Pro
B25: Итого | C25: =SUM(C5:C24) | D25: экспонатов фонда пришло за 20 лет
